Workbook

Sheet 6c05cd1b-ed59-40c2-bc31-e314f39
A1: State | B1: District | C1: Date | D1: Year | E1: Month | F1: Avg_rainfall | G1: Agency_name
A2: Puducherry | B2: Pondicherry | C2: 43747 | D2: 2019 | E2: 10 | F2: 0 | G2: IMD GRID MODEL
A3: Puducherry | B3: Pondicherry | C3: 43748 | D3: 2019 | E3: 10 | F3: 0 | G3: IMD GRID MODEL
A4: Puducherry | B4: Pondicherry | C4: 43754 | D4: 2019 | E4: 10 | F4: 8.3884455 | G4: IMD GRID MODEL
A5: Puducherry | B5: Pondicherry | C5: 43764 | D5: 2019 | E5: 10 | F5: 1.6941764 | G5: IMD GRID MODEL
A6: Puducherry | B6: Pondicherry | C6: 43771 | D6: 2019 | E6: 11 | F6: 0.02901784 | G6: IMD GRID MODEL
A7: Puducherry | B7: Pondicherry | C7: 43773 | D7: 2019 | E7: 11 | F7: 0.017113085 | G7: IMD GRID MODEL
A8: Puducherry | B8: Pondicherry | C8: 43789 | D8: 2019 | E8: 11 | F8: 12.058279 | G8: IMD GRID MODEL
A9: Puducherry | B9: Pondicherry | C9: 43796 | D9: 2019 | E9: 11 | F9: 28.054364 | G9: IMD GRID MODEL
A10: Puducherry | B10: Pondicherry | C10: 43798 | D10: 2019 | E10: 11 | F10: 14.344628 | G10: IMD GRID MODEL
A11: Puducherry | B11: Pondicherry | C11: 43799 | D11: 2019 | E11: 11 | F11: 17.91026 | G11: IMD GRID MODEL
A12: Puducherry | B12: Pondicherry | C12: 43809 | D12: 2019 | E12: 12 | F12: 0 | G12: IMD GRID MODEL
A13: Puducherry | B13: Pondicherry | C13: 43819 | D13: 2019 | E13: 12 | F13: 0 | G13: IMD GRID MODEL
... A1461: Puducherry | B1461: Mahe | C1461: 43694 | D1461: 2019 | E1461: 8 | F1461: 4.8954902 | G1461: IMD GRID MODEL

Sheet Monthly_Rainfall
A1: District | B1: Year | C1: Month | D1: Total_Rainfall
A2: Karaikal | B2: 2019 | C2: 1 | D2: 0
A3: Karaikal | B3: 2019 | C3: 2 | D3: 9.1658143
A4: Karaikal | B4: 2019 | C4: 3 | D4: 0.92913429
A5: Karaikal | B5: 2019 | C5: 4 | D5: 0.15261144
A6: Karaikal | B6: 2019 | C6: 5 | D6: 0
A7: Karaikal | B7: 2019 | C7: 6 | D7: 13.349442
A8: Karaikal | B8: 2019 | C8: 7 | D8: 23.672272
A9: Karaikal | B9: 2019 | C9: 8 | D9: 109.44944
A10: Karaikal | B10: 2019 | C10: 9 | D10: 178.71327
A11: Karaikal | B11: 2019 | C11: 10 | D11: 339.9321
A12: Karaikal | B12: 2019 | C12: 11 | D12: 353.01902
A13: Karaikal | B13: 2019 | C13: 12 | D13: 355.84132
... A49: Yanam | B49: 2019 | C49: 12 | D49: 0.2774348

Sheet Sheet6
A3: Row Labels | B3: Sum of Avg_rainfall | C3: Days_with_Data
A4: Karaikal | B4: 1384.2244 | C4: 365
A5: 2019 | B5: 1384.2244 | C5: 365
A6: 1 | B6: 0 | C6: 31
A7: 2 | B7: 9.1658143 | C7: 28
A8: 3 | B8: 0.92913429 | C8: 31
A9: 4 | B9: 0.15261144 | C9: 30
A10: 5 | B10: 0 | C10: 31
A11: 6 | B11: 13.349442 | C11: 30
A12: 7 | B12: 23.672272 | C12: 31
A13: 8 | B13: 109.44944 | C13: 31
A14: 9 | B14: 178.71327 | C14: 30
A15: 10 | B15: 339.9321 | C15: 31
A16: 11 | B16: 353.01902 | C16: 30
A17: 12 | B17: 355.84132 | C17: 31
A18: Mahe | B18: 4426.9431 | C18: 365
A19: 2019 | B19: 4426.9431 | C19: 365
A20: 1 | B20: 0 | C20: 31
A21: 2 | B21: 0 | C21: 28
A22: 3 | B22: 0 | C22: 31
A23: 4 | B23: 32.637676 | C23: 30
A24: 5 | B24: 41.663589 | C24: 31
A25: 6 | B25: 610.4494 | C25: 30
A26: 7 | B26: 1076.7193 | C26: 31
A27: 8 | B27: 1450.6353 | C27: 31
A28: 9 | B28: 520.47047 | C28: 30
A29: 10 | B29: 543.82237 | C29: 31
A30: 11 | B30: 106.62843 | C30: 30
A31: 12 | B31: 43.916472 | C31: 31
A32: Pondicherry | B32: 1130.3149 | C32: 365
A33: 2019 | B33: 1130.3149 | C33: 365
A34: 1 | B34: 0.34661179 | C34: 31
A35: 2 | B35: 0 | C35: 28
A36: 3 | B36: 0 | C36: 31
A37: 4 | B37: 0.22935671 | C37: 30
A38: 5 | B38: 13.982448 | C38: 31
A39: 6 | B39: 14.047029 | C39: 30
A40: 7 | B40: 106.98965 | C40: 31
A41: 8 | B41: 153.04124 | C41: 31
A42: 9 | B42: 141.01451 | C42: 30
...

Sheet raw_rainfall
A1: State | B1: District | C1: Date | D1: Year | E1: Month | F1: Avg_rainfall | G1: Agency_name
A2: Puducherry | B2: Pondicherry | C2: 43747 | D2: 2019 | E2: 10 | F2: 0 | G2: IMD GRID MODEL
A3: Puducherry | B3: Pondicherry | C3: 43748 | D3: 2019 | E3: 10 | F3: 0 | G3: IMD GRID MODEL
A4: Puducherry | B4: Pondicherry | C4: 43754 | D4: 2019 | E4: 10 | F4: 8.3884455 | G4: IMD GRID MODEL
A5: Puducherry | B5: Pondicherry | C5: 43764 | D5: 2019 | E5: 10 | F5: 1.6941764 | G5: IMD GRID MODEL
A6: Puducherry | B6: Pondicherry | C6: 43771 | D6: 2019 | E6: 11 | F6: 0.02901784 | G6: IMD GRID MODEL
A7: Puducherry | B7: Pondicherry | C7: 43773 | D7: 2019 | E7: 11 | F7: 0.017113085 | G7: IMD GRID MODEL
A8: Puducherry | B8: Pondicherry | C8: 43789 | D8: 2019 | E8: 11 | F8: 12.058279 | G8: IMD GRID MODEL
A9: Puducherry | B9: Pondicherry | C9: 43796 | D9: 2019 | E9: 11 | F9: 28.054364 | G9: IMD GRID MODEL
A10: Puducherry | B10: Pondicherry | C10: 43798 | D10: 2019 | E10: 11 | F10: 14.344628 | G10: IMD GRID MODEL
A11: Puducherry | B11: Pondicherry | C11: 43799 | D11: 2019 | E11: 11 | F11: 17.91026 | G11: IMD GRID MODEL
A12: Puducherry | B12: Pondicherry | C12: 43809 | D12: 2019 | E12: 12 | F12: 0 | G12: IMD GRID MODEL
A13: Puducherry | B13: Pondicherry | C13: 43819 | D13: 2019 | E13: 12 | F13: 0 | G13: IMD GRID MODEL
... A1461: Puducherry | B1461: Mahe | C1461: 43694 | D1461: 2019 | E1461: 8 | F1461: 4.8954902 | G1461: IMD GRID MODEL

Sheet Sheet1
A1: S.No. | B1: State/UT | C1: 2019 - January | D1: 2019 - February | E1: 2019 - March | F1: 2019 - April | G1: 2019 - May | H1: 2019 - June | I1: 2019 - Total | J1: 2018 - January | K1: 2018 - February | L1: 2018 - March | M1: 2018 - April | N1: 2018 - May | O1: 2018 - June | P1: 2018 - July | Q1: 2018 - August | R1: 2018 - September | S1: 2018 - October | T1: 2018 - November | U1: 2018 - December | V1: 2018 - Total
A2: 1 | B2: Andhara Pradesh | C2: 62 | D2: 32 | E2: 56 | F2: 87 | G2: 71 | H2: 141 | I2: 449 | J2: 90 | K2: 81 | L2: 77 | M2: 46 | N2: 69 | O2: 285 | P2: 928 | Q2: 1162 | R2: 576 | S2: 348 | T2: 199 | U2: 150 | V2: 4011
A3: 2 | B3: Arunachal Pradesh | C3: 0 | D3: 0 | E3: 0 | F3: 0 | G3: 0 | H3: 0 | I3: 0 | J3: 0 | K3: 0 | L3: 0 | M3: 0 | N3: 0 | O3: 0 | P3: 0 | Q3: 1 | R3: 0 | S3: 0 | T3: 0 | U3: 0 | V3: 1
A4: 3 | B4: Assam | C4: 0 | D4: 4 | E4: 4 | F4: 3 | G4: 3 | H4: 3 | I4: 17 | J4: 2 | K4: 1 | L4: 2 | M4: 2 | N4: 3 | O4: 20 | P4: 17 | Q4: 10 | R4: 20 | S4: 30 | T4: 56 | U4: 3 | V4: 166
A5: 4 | B5: Bihar | C5: 0 | D5: 0 | E5: 0 | F5: 0 | G5: 3 | H5: 2 | I5: 5 | J5: 2 | K5: 0 | L5: 0 | M5: 0 | N5: 0 | O5: 3 | P5: 3 | Q5: 45 | R5: 166 | S5: 841 | T5: 1028 | U5: 54 | V5: 2142
A6: 5 | B6: Chhattisgarh | C6: 18 | D6: 23 | E6: 12 | F6: 5 | G6: 30 | H6: 8 | I6: 96 | J6: 3 | K6: 4 | L6: 1 | M6: 0 | N6: 3 | O6: 7 | P6: 170 | Q6: 587 | R6: 1200 | S6: 465 | T6: 189 | U6: 45 | V6: 2674
A7: 6 | B7: Goa | C7: 16 | D7: 7 | E7: 8 | F7: 9 | G7: 6 | H7: 47 | I7: 93 | J7: 20 | K7: 8 | L7: 11 | M7: 7 | N7: 10 | O7: 68 | P7: 71 | Q7: 41 | R7: 36 | S7: 31 | T7: 19 | U7: 13 | V7: 335
A8: 7 | B8: Gujarat | C8: 111 | D8: 55 | E8: 59 | F8: 39 | G8: 76 | H8: 54 | I8: 394 | J8: 141 | K8: 102 | L8: 89 | M8: 72 | N8: 100 | O8: 76 | P8: 196 | Q8: 583 | R8: 1518 | S8: 2854 | T8: 1347 | U8: 501 | V8: 7579
A9: 8 | B9: Haryana | C9: 0 | D9: 0 | E9: 0 | F9: 0 | G9: 2 | H9: 1 | I9: 3 | J9: 0 | K9: 0 | L9: 0 | M9: 3 | N9: 2 | O9: 2 | P9: 9 | Q9: 40 | R9: 245 | S9: 768 | T9: 685 | U9: 144 | V9: 1898
A10: 9 | B10: Himachal Pradesh | C10: 5 | D10: 4 | E10: 1 | F10: 3 | G10: 1 | H10: 4 | I10: 18 | J10: 0 | K10: 0 | L10: 0 | M10: 0 | N10: 0 | O10: 65 | P10: 481 | Q10: 1276 | R10: 1481 | S10: 1131 | T10: 228 | U10: 10 | V10: 4672
A11: 10 | B11: J & K | C11: 0 | D11: 0 | E11: 0 | F11: 0 | G11: 0 | H11: 0 | I11: 0 | J11: 0 | K11: 0 | L11: 0 | M11: 0 | N11: 1 | O11: 0 | P11: 1 | Q11: 0 | R11: 21 | S11: 131 | T11: 53 | U11: 7 | V11: 214
A12: 11 | B12: Jharkhand | C12: 5 | D12: 1 | E12: 6 | F12: 10 | G12: 4 | H12: 6 | I12: 32 | J12: 1 | K12: 0 | L12: 0 | M12: 3 | N12: 3 | O12: 7 | P12: 18 | Q12: 103 | R12: 104 | S12: 77 | T12: 126 | U12: 21 | V12: 463
A13: 12 | B13: Karnataka | C13: 51 | D13: 199 | E13: 247 | F13: 219 | G13: 414 | H13: 803 | I13: 1933 | J13: 154 | K13: 298 | L13: 230 | M13: 138 | N13: 186 | O13: 415 | P13: 606 | Q13: 362 | R13: 300 | S13: 601 | T13: 318 | U13: 819 | V13: 4427
... A29: 28 | B29: Uttrakhand | C29: 0 | D29: 0 | E29: 0 | F29: 0 | G29: 0 | H29: 0 | I29: 0 | J29: 0 | K29: 0 | L29: 0 | M29: 0 | N29: 0 | O29: 0 | P29: 6 | Q29: 10 | R29: 190 | S29: 335 | T29: 148 | U29: 0 | V29: 689
A30: 29 | B30: West Bengal | C30: Not Reported | D30: Not Reported | E30: Not Reported | F30: Not Reported | G30: Not Reported | H30: Not Reported | I30: Not Reported | J30: Not Reported | K30: Not Reported | L30: Not Reported | M30: Not Reported | N30: Not Reported | O30: Not Reported | P30: Not Reported | Q30: Not Reported | R30: Not Reported | S30: Not Reported | T30: Not Reported | U30: Not Reported | V30: Not Reported
A31: 30 | B31: A&N Island | C31: 24 | D31: 0 | E31: 0 | F31: 0 | G31: 1 | H31: 0 | I31: 25 | J31: 0 | K31: 1 | L31: 2 | M31: 1 | N31: 5 | O31: 2 | P31: 0 | Q31: 0 | R31: 10 | S31: 12 | T31: 6 | U31: 10 | V31: 49
A32: 31 | B32: Chandigarh | C32: 0 | D32: 0 | E32: 0 | F32: 0 | G32: 0 | H32: 7 | I32: 7 | J32: 3 | K32: 1 | L32: 1 | M32: 0 | N32: 2 | O32: 5 | P32: 5 | Q32: 17 | R32: 56 | S32: 115 | T32: 80 | U32: 16 | V32: 301
A33: 32 | B33: Delhi | C33: 1 | D33: 18 | E33: 5 | F33: 16 | G33: 13 | H33: 38 | I33: 91 | J33: 5 | K33: 10 | L33: 3 | M33: 8 | N33: 8 | O33: 24 | P33: 49 | Q33: 160 | R33: 889 | S33: 2245 | T33: 2813 | U33: 922 | V33: 7136
A34: 33 | B34: D&N Haveli | C34: 0 | D34: 4 | E34: 4 | F34: 4 | G34: 4 | H34: 6 | I34: 22 | J34: 13 | K34: 3 | L34: 4 | M34: 7 | N34: 11 | O34: 25 | P34: 18 | Q34: 44 | R34: 85 | S34: 160 | T34: 94 | U34: 29 | V34: 493
A35: 34 | B35: Daman & Diu | C35: 0 | D35: 0 | E35: 0 | F35: 0 | G35: 0 | H35: 1 | I35: 1 | J35: 2 | K35: 1 | L35: 0 | M35: 0 | N35: 0 | O35: 4 | P35: 3 | Q35: 8 | R35: 36 | S35: 60 | T35: 35 | U35: 14 | V35: 163
A36: 35 | B36: Puducherry | C36: 64 | D36: 72 | E36: 49 | F36: 60 | G36: 23 | H36: 27 | I36: 295 | J36: 60 | K36: 31 | L36: 5 | M36: 4 | N36: 3 | O36: 2 | P36: 9 | Q36: 15 | R36: 51 | S36: 95 | T36: 179 | U36: 138 | V36: 592
A37: Total | B37: Total | C37: 1206 | D37: 967 | E37: 1156 | F37: 1008 | G37: 1379 | H37: 2342 | I37: 8058 | J37: 2305 | K37: 1409 | L37: 1060 | M37: 948 | N37: 1535 | O37: 3658 | P37: 5815 | Q37: 10092 | R37: 16877 | S37: 30125 | T37: 20852 | U37: 6516 | V37: 101192

Sheet Merged_Analysis
A1: District | B1: Year | C1: Month | D1: Total_Rainfall | E1: Year_Month | F1: Dengue_Cases | G1: Rainfall_Lag1 | H1: Rainfall_Lag2
A2: Karaikal | B2: 2019 | C2: 1 | D2: 0 | E2: =B2&"-"&C2 -> 2019-1 | F2: =IFERROR(INDEX(Dengue_CAses!$D$2:$D$13,MATCH(E2,Dengue_CAses!$E$2:$E$13,0)),0) -> 64
A3: Karaikal | B3: 2019 | C3: 2 | D3: 9.1658143 | E3: =B3&"-"&C3 -> 2019-2 | F3: =IFERROR(INDEX(Dengue_CAses!$D$2:$D$13,MATCH(E3,Dengue_CAses!$E$2:$E$13,0)),0) -> 72 | G3: =D2 -> 0
A4: Karaikal | B4: 2019 | C4: 3 | D4: 0.92913429 | E4: =B4&"-"&C4 -> 2019-3 | F4: =IFERROR(INDEX(Dengue_CAses!$D$2:$D$13,MATCH(E4,Dengue_CAses!$E$2:$E$13,0)),0) -> 49 | G4: =D3 -> 9.1658143 | H4: =D2 -> 0
A5: Karaikal | B5: 2019 | C5: 4 | D5: 0.15261144 | E5: =B5&"-"&C5 -> 2019-4 | F5: =IFERROR(INDEX(Dengue_CAses!$D$2:$D$13,MATCH(E5,Dengue_CAses!$E$2:$E$13,0)),0) -> 60 | G5: =D4 -> 0.92913429 | H5: =D3 -> 9.1658143
A6: Karaikal | B6: 2019 | C6: 5 | D6: 0 | E6: =B6&"-"&C6 -> 2019-5 | F6: =IFERROR(INDEX(Dengue_CAses!$D$2:$D$13,MATCH(E6,Dengue_CAses!$E$2:$E$13,0)),0) -> 23 | G6: =D5 -> 0.15261144 | H6: =D4 -> 0.92913429
A7: Karaikal | B7: 2019 | C7: 6 | D7: 13.349442 | E7: =B7&"-"&C7 -> 2019-6 | F7: =IFERROR(INDEX(Dengue_CAses!$D$2:$D$13,MATCH(E7,Dengue_CAses!$E$2:$E$13,0)),0) -> 27 | G7: =D6 -> 0 | H7: =D5 -> 0.15261144
A8: Karaikal | B8: 2019 | C8: 7 | D8: 23.672272 | E8: =B8&"-"&C8 -> 2019-7 | F8: =IFERROR(INDEX(Dengue_CAses!$D$2:$D$13,MATCH(E8,Dengue_CAses!$E$2:$E$13,0)),0) -> 0 | G8: =D7 -> 13.349442 | H8: =D6 -> 0
A9: Karaikal | B9: 2019 | C9: 8 | D9: 109.44944 | E9: =B9&"-"&C9 -> 2019-8 | F9: =IFERROR(INDEX(Dengue_CAses!$D$2:$D$13,MATCH(E9,Dengue_CAses!$E$2:$E$13,0)),0) -> 0 | G9: =D8 -> 23.672272 | H9: =D7 -> 13.349442
A10: Karaikal | B10: 2019 | C10: 9 | D10: 178.71327 | E10: =B10&"-"&C10 -> 2019-9 | F10: =IFERROR(INDEX(Dengue_CAses!$D$2:$D$13,MATCH(E10,Dengue_CAses!$E$2:$E$13,0)),0) -> 0 | G10: =D9 -> 109.44944 | H10: =D8 -> 23.672272
A11: Karaikal | B11: 2019 | C11: 10 | D11: 339.9321 | E11: =B11&"-"&C11 -> 2019-10 | F11: =IFERROR(INDEX(Dengue_CAses!$D$2:$D$13,MATCH(E11,Dengue_CAses!$E$2:$E$13,0)),0) -> 0 | G11: =D10 -> 178.71327 | H11: =D9 -> 109.44944
A12: Karaikal | B12: 2019 | C12: 11 | D12: 353.01902 | E12: =B12&"-"&C12 -> 2019-11 | F12: =IFERROR(INDEX(Dengue_CAses!$D$2:$D$13,MATCH(E12,Dengue_CAses!$E$2:$E$13,0)),0) -> 0 | G12: =D11 -> 339.9321 | H12: =D10 -> 178.71327
A13: Karaikal | B13: 2019 | C13: 12 | D13: 355.84132 | E13: =B13&"-"&C13 -> 2019-12 | F13: =IFERROR(INDEX(Dengue_CAses!$D$2:$D$13,MATCH(E13,Dengue_CAses!$E$2:$E$13,0)),0) -> 0 | G13: =D12 -> 353.01902 | H13: =D11 -> 339.9321
A14: Mahe | B14: 2019 | C14: 1 | D14: 0 | E14: =B14&"-"&C14 -> 2019-1 | F14: =IFERROR(INDEX(Dengue_CAses!$D$2:$D$13,MATCH(E14,Dengue_CAses!$E$2:$E$13,0)),0) -> 64 | G14: =D13 -> 355.84132 | H14: =D12 -> 353.01902
A15: Mahe | B15: 2019 | C15: 2 | D15: 0 | E15: =B15&"-"&C15 -> 2019-2 | F15: =IFERROR(INDEX(Dengue_CAses!$D$2:$D$13,MATCH(E15,Dengue_CAses!$E$2:$E$13,0)),0) -> 72 | G15: =D14 -> 0 | H15: =D13 -> 355.84132
... A49: Yanam | B49: 2019 | C49: 12 | D49: 0.2774348 | E49: =B49&"-"&C49 -> 2019-12 | F49: =IFERROR(INDEX(Dengue_CAses!$D$2:$D$13,MATCH(E49,Dengue_CAses!$E$2:$E$13,0)),0) -> 0 | G49: =D48 -> 10.345064 | H49: =D47 -> 213.0449
A55: ========================================================================
B56: CORRELATION ANALYSIS
A57: ========================================================================
A59: Lag Type | B59: Correlation Value
A60: Same Month(Lag 0) | B60: =CORREL(D2:D49,F2:F49) -> -0.45617371
A61: 1-Month Lag | B61: =CORREL(G3:G49,F3:F49) -> -0.39818084
A62: 2-Month Lag | B62: =CORREL(H4:H49,F4:F49) -> -0.2586229

Sheet Charts
A1: Month | B1: Total_Rainfall | C1: Dengue_Cases | F1: District | G1: Total_Rainfall
A2: 1 | B2: 0.34661179 | C2: 64 | F2: Pondicherry | G2: =SUMIF(Merged_Analysis!A:A,"Pondicherry",Merged_Analysis!D:D) -> 1130.3149
A3: 2 | B3: 0 | C3: 72 | F3: Karaikal | G3: =SUMIF(Merged_Analysis!A:A,"Karaikal",Merged_Analysis!D:D) -> 1384.2244
A4: 3 | B4: 0 | C4: 49 | F4: Mahe | G4: =SUMIF(Merged_Analysis!A:A,"Mahe",Merged_Analysis!D:D) -> 4426.9431
A5: 4 | B5: 0.22935671 | C5: 60 | F5: Yanam | G5: =SUMIF(Merged_Analysis!A:A,"Yanam",Merged_Analysis!D:D) -> 1153.7339
A6: 5 | B6: 13.982448 | C6: 23
A7: 6 | B7: 14.047029 | C7: 27
F8: Lag_Type | G8: Correlation
F9: Lag 0 | G9: -0.333
F10: Lag 1 | G10: 0.161
F11: Lag 2 | G11: 0.547

Sheet Final_Merged_Analysis
A1: District | B1: Year | C1: Month | D1: Total_Rainfall | E1: Year_Month | F1: Dengue_Cases | G1: Rainfall_Lag1 | H1: Rainfall_Lag2
A2: Karaikal | B2: 2019 | C2: 1 | D2: 0 | E2: =B2&"-"&C2 -> 2019-1 | F2: =IFERROR(INDEX(Dengue_CAses!$D$2:$D$13,MATCH(E2,Dengue_CAses!$E$2:$E$13,0)),0) -> 64
A3: Karaikal | B3: 2019 | C3: 2 | D3: 9.1658143 | E3: =B3&"-"&C3 -> 2019-2 | F3: =IFERROR(INDEX(Dengue_CAses!$D$2:$D$13,MATCH(E3,Dengue_CAses!$E$2:$E$13,0)),0) -> 72 | G3: =D2 -> 0
A4: Karaikal | B4: 2019 | C4: 3 | D4: 0.92913429 | E4: =B4&"-"&C4 -> 2019-3 | F4: =IFERROR(INDEX(Dengue_CAses!$D$2:$D$13,MATCH(E4,Dengue_CAses!$E$2:$E$13,0)),0) -> 49 | G4: =D3 -> 9.1658143 | H4: =D2 -> 0
A5: Karaikal | B5: 2019 | C5: 4 | D5: 0.15261144 | E5: =B5&"-"&C5 -> 2019-4 | F5: =IFERROR(INDEX(Dengue_CAses!$D$2:$D$13,MATCH(E5,Dengue_CAses!$E$2:$E$13,0)),0) -> 60 | G5: =D4 -> 0.92913429 | H5: =D3 -> 9.1658143
A6: Karaikal | B6: 2019 | C6: 5 | D6: 0 | E6: =B6&"-"&C6 -> 2019-5 | F6: =IFERROR(INDEX(Dengue_CAses!$D$2:$D$13,MATCH(E6,Dengue_CAses!$E$2:$E$13,0)),0) -> 23 | G6: =D5 -> 0.15261144 | H6: =D4 -> 0.92913429
A7: Karaikal | B7: 2019 | C7: 6 | D7: 13.349442 | E7: =B7&"-"&C7 -> 2019-6 | F7: =IFERROR(INDEX(Dengue_CAses!$D$2:$D$13,MATCH(E7,Dengue_CAses!$E$2:$E$13,0)),0) -> 27 | G7: =D6 -> 0 | H7: =D5 -> 0.15261144
A8: Karaikal | B8: 2019 | C8: 7 | D8: 23.672272 | E8: =B8&"-"&C8 -> 2019-7 | G8: =D7 -> 13.349442 | H8: =D6 -> 0
A9: Karaikal | B9: 2019 | C9: 8 | D9: 109.44944 | E9: =B9&"-"&C9 -> 2019-8 | G9: =D8 -> 23.672272 | H9: =D7 -> 13.349442
A10: Karaikal | B10: 2019 | C10: 9 | D10: 178.71327 | E10: =B10&"-"&C10 -> 2019-9 | G10: =D9 -> 109.44944 | H10: =D8 -> 23.672272
A11: Karaikal | B11: 2019 | C11: 10 | D11: 339.9321 | E11: =B11&"-"&C11 -> 2019-10 | G11: =D10 -> 178.71327 | H11: =D9 -> 109.44944
A12: Karaikal | B12: 2019 | C12: 11 | D12: 353.01902 | E12: =B12&"-"&C12 -> 2019-11 | G12: =D11 -> 339.9321 | H12: =D10 -> 178.71327
A13: Karaikal | B13: 2019 | C13: 12 | D13: 355.84132 | E13: =B13&"-"&C13 -> 2019-12 | G13: =D12 -> 353.01902 | H13: =D11 -> 339.9321
A14: Mahe | B14: 2019 | C14: 1 | D14: 0 | E14: =B14&"-"&C14 -> 2019-1 | F14: =IFERROR(INDEX(Dengue_CAses!$D$2:$D$13,MATCH(E14,Dengue_CAses!$E$2:$E$13,0)),0) -> 64 | G14: =D13 -> 355.84132 | H14: =D12 -> 353.01902
A15: Mahe | B15: 2019 | C15: 2 | D15: 0 | E15: =B15&"-"&C15 -> 2019-2 | F15: =IFERROR(INDEX(Dengue_CAses!$D$2:$D$13,MATCH(E15,Dengue_CAses!$E$2:$E$13,0)),0) -> 72 | G15: =D14 -> 0 | H15: =D13 -> 355.84132
A16: Mahe | B16: 2019 | C16: 3 | D16: 0 | E16: =B16&"-"&C16 -> 2019-3 | F16: =IFERROR(INDEX(Dengue_CAses!$D$2:$D$13,MATCH(E16,Dengue_CAses!$E$2:$E$13,0)),0) -> 49 | G16: =D15 -> 0 | H16: =D14 -> 0
A17: Mahe | B17: 2019 | C17: 4 | D17: 32.637676 | E17: =B17&"-"&C17 -> 2019-4 | F17: =IFERROR(INDEX(Dengue_CAses!$D$2:$D$13,MATCH(E17,Dengue_CAses!$E$2:$E$13,0)),0) -> 60 | G17: =D16 -> 0 | H17: =D15 -> 0
A18: Mahe | B18: 2019 | C18: 5 | D18: 41.663589 | E18: =B18&"-"&C18 -> 2019-5 | F18: =IFERROR(INDEX(Dengue_CAses!$D$2:$D$13,MATCH(E18,Dengue_CAses!$E$2:$E$13,0)),0) -> 23 | G18: =D17 -> 32.637676 | H18: =D16 -> 0
A19: Mahe | B19: 2019 | C19: 6 | D19: 610.4494 | E19: =B19&"-"&C19 -> 2019-6 | F19: =IFERROR(INDEX(Dengue_CAses!$D$2:$D$13,MATCH(E19,Dengue_CAses!$E$2:$E$13,0)),0) -> 27 | G19: =D18 -> 41.663589 | H19: =D17 -> 32.637676
A20: Mahe | B20: 2019 | C20: 7 | D20: 1076.7193 | E20: =B20&"-"&C20 -> 2019-7 | G20: =D19 -> 610.4494 | H20: =D18 -> 41.663589
A21: Mahe | B21: 2019 | C21: 8 | D21: 1450.6353 | E21: =B21&"-"&C21 -> 2019-8 | G21: =D20 -> 1076.7193 | H21: =D19 -> 610.4494
A22: Mahe | B22: 2019 | C22: 9 | D22: 520.47047 | E22: =B22&"-"&C22 -> 2019-9 | G22: =D21 -> 1450.6353 | H22: =D20 -> 1076.7193
A23: Mahe | B23: 2019 | C23: 10 | D23: 543.82237 | E23: =B23&"-"&C23 -> 2019-10 | G23: =D22 -> 520.47047 | H23: =D21 -> 1450.6353
A24: Mahe | B24: 2019 | C24: 11 | D24: 106.62843 | E24: =B24&"-"&C24 -> 2019-11 | G24: =D23 -> 543.82237 | H24: =D22 -> 520.47047
A25: Mahe | B25: 2019 | C25: 12 | D25: 43.916472 | E25: =B25&"-"&C25 -> 2019-12 | G25: =D24 -> 106.62843 | H25: =D23 -> 543.82237
A26: Pondicherry | B26: 2019 | C26: 1 | D26: 0.34661179 | E26: =B26&"-"&C26 -> 2019-1 | F26: =IFERROR(INDEX(Dengue_CAses!$D$2:$D$13,MATCH(E26,Dengue_CAses!$E$2:$E$13,0)),0) -> 64 | G26: =D25 -> 43.916472 | H26: =D24 -> 106.62843
A27: Pondicherry | B27: 2019 | C27: 2 | D27: 0 | E27: =B27&"-"&C27 -> 2019-2 | F27: =IFERROR(INDEX(Dengue_CAses!$D$2:$D$13,MATCH(E27,Dengue_CAses!$E$2:$E$13,0)),0) -> 72 | G27: =D26 -> 0.34661179 | H27: =D25 -> 43.916472
A28: Pondicherry | B28: 2019 | C28: 3 | D28: 0 | E28: =B28&"-"&C28 -> 2019-3 | F28: =IFERROR(INDEX(Dengue_CAses!$D$2:$D$13,MATCH(E28,Dengue_CAses!$E$2:$E$13,0)),0) -> 49 | G28: =D27 -> 0 | H28: =D26 -> 0.34661179
A29: Pondicherry | B29: 2019 | C29: 4 | D29: 0.22935671 | E29: =B29&"-"&C29 -> 2019-4 | F29: =IFERROR(INDEX(Dengue_CAses!$D$2:$D$13,MATCH(E29,Dengue_CAses!$E$2:$E$13,0)),0) -> 60 | G29: =D28 -> 0 | H29: =D27 -> 0
A30: Pondicherry | B30: 2019 | C30: 5 | D30: 13.982448 | E30: =B30&"-"&C30 -> 2019-5 | F30: =IFERROR(INDEX(Dengue_CAses!$D$2:$D$13,MATCH(E30,Dengue_CAses!$E$2:$E$13,0)),0) -> 23 | G30: =D29 -> 0.22935671 | H30: =D28 -> 0
A31: Pondicherry | B31: 2019 | C31: 6 | D31: 14.047029 | E31: =B31&"-"&C31 -> 2019-6 | F31: =IFERROR(INDEX(Dengue_CAses!$D$2:$D$13,MATCH(E31,Dengue_CAses!$E$2:$E$13,0)),0) -> 27 | G31: =D30 -> 13.982448 | H31: =D29 -> 0.22935671
A32: Pondicherry | B32: 2019 | C32: 7 | D32: 106.98965 | E32: =B32&"-"&C32 -> 2019-7 | G32: =D31 -> 14.047029 | H32: =D30 -> 13.982448
A33: Pondicherry | B33: 2019 | C33: 8 | D33: 153.04124 | E33: =B33&"-"&C33 -> 2019-8 | G33: =D32 -> 106.98965 | H33: =D31 -> 14.047029
A34: Pondicherry | B34: 2019 | C34: 9 | D34: 141.01451 | E34: =B34&"-"&C34 -> 2019-9 | G34: =D33 -> 153.04124 | H34: =D32 -> 106.98965
A35: Pondicherry | B35: 2019 | C35: 10 | D35: 238.07444 | E35: =B35&"-"&C35 -> 2019-10 | G35: =D34 -> 141.01451 | H35: =D33 -> 153.04124
A36: Pondicherry | B36: 2019 | C36: 11 | D36: 216.28458 | E36: =B36&"-"&C36 -> 2019-11 | G36: =D35 -> 238.07444 | H36: =D34 -> 141.01451
A37: Pondicherry | B37: 2019 | C37: 12 | D37: 246.30506 | E37: =B37&"-"&C37 -> 2019-12 | G37: =D36 -> 216.28458 | H37: =D35 -> 238.07444
A38: Yanam | B38: 2019 | C38: 1 | D38: 4.8676038 | E38: =B38&"-"&C38 -> 2019-1 | F38: =IFERROR(INDEX(Dengue_CAses!$D$2:$D$13,MATCH(E38,Dengue_CAses!$E$2:$E$13,0)),0) -> 64 | G38: =D37 -> 246.30506 | H38: =D36 -> 216.28458
A39: Yanam | B39: 2019 | C39: 2 | D39: 0 | E39: =B39&"-"&C39 -> 2019-2 | F39: =IFERROR(INDEX(Dengue_CAses!$D$2:$D$13,MATCH(E39,Dengue_CAses!$E$2:$E$13,0)),0) -> 72 | G39: =D38 -> 4.8676038 | H39: =D37 -> 246.30506
A40: Yanam | B40: 2019 | C40: 3 | D40: 17.475863 | E40: =B40&"-"&C40 -> 2019-3 | F40: =IFERROR(INDEX(Dengue_CAses!$D$2:$D$13,MATCH(E40,Dengue_CAses!$E$2:$E$13,0)),0) -> 49 | G40: =D39 -> 0 | H40: =D38 -> 4.8676038
...

Sheet Sheet5
A1: District | B1: Year | C1: Month | D1: Total_Rainfall | E1: Year_Month | F1: Dengue_Cases | G1: Rainfall_Lag1 | H1: Rainfall_Lag2
A2: Pondicherry | B2: 2019 | C2: 1 | D2: 0.34661179 | E2: 2019-1 | F2: 64 | G2: 43.916472 | H2: 106.62843
A3: Pondicherry | B3: 2019 | C3: 2 | D3: 0 | E3: 2019-2 | F3: 72 | G3: 0.34661179 | H3: 43.916472
A4: Pondicherry | B4: 2019 | C4: 3 | D4: 0 | E4: 2019-3 | F4: 49 | G4: 0 | H4: 0.34661179
A5: Pondicherry | B5: 2019 | C5: 4 | D5: 0.22935671 | E5: 2019-4 | F5: 60 | G5: 0 | H5: 0
A6: Pondicherry | B6: 2019 | C6: 5 | D6: 13.982448 | E6: 2019-5 | F6: 23 | G6: 0.22935671 | H6: 0
A7: Pondicherry | B7: 2019 | C7: 6 | D7: 14.047029 | E7: 2019-6 | F7: 27 | G7: 13.982448 | H7: 0.22935671

Sheet Dengue_CAses
A1: State | B1: Year | C1: Month | D1: Dengue_cases | E1: Year_Month
A2: Puducherry | B2: 2019 | C2: 1 | D2: 64 | E2: =B2&"-"&C2 -> 2019-1
A3: Puducherry | B3: 2019 | C3: 2 | D3: 72 | E3: =B3&"-"&C3 -> 2019-2
A4: Puducherry | B4: 2019 | C4: 3 | D4: 49 | E4: =B4&"-"&C4 -> 2019-3
A5: Puducherry | B5: 2019 | C5: 4 | D5: 60 | E5: =B5&"-"&C5 -> 2019-4
A6: Puducherry | B6: 2019 | C6: 5 | D6: 23 | E6: =B6&"-"&C6 -> 2019-5
A7: Puducherry | B7: 2019 | C7: 6 | D7: 27 | E7: =B7&"-"&C7 -> 2019-6
A8: Puducherry | B8: 2019 | C8: 7 | E8: =B8&"-"&C8 -> 2019-7
A9: Puducherry | B9: 2019 | C9: 8 | E9: =B9&"-"&C9 -> 2019-8
A10: Puducherry | B10: 2019 | C10: 9 | E10: =B10&"-"&C10 -> 2019-9
A11: Puducherry | B11: 2019 | C11: 10 | E11: =B11&"-"&C11 -> 2019-10
A12: Puducherry | B12: 2019 | C12: 11 | E12: =B12&"-"&C12 -> 2019-11
A13: Puducherry | B13: 2019 | C13: 12 | E13: =B13&"-"&C13 -> 2019-12
